<?xml version="1.0" encoding="utf-8"?>
<!-- This URDF was automatically created by SolidWorks to URDF Exporter! Originally created by Stephen Brawner (brawner@gmail.com) 
     Commit Version: 1.6.0-1-g15f4949  Build Version: 1.6.7594.29634
     For more information, please see http://wiki.ros.org/sw_urdf_exporter -->
<robot
  name="blue02">
  <link
    name="base_link">
    <inertial>
      <origin
        xyz="0.0001808612784363 0.0180191600373319 -0.0010066992638707"
        rpy="0 0 0" />
      <mass
        value="0.222069356338279" />
      <inertia
        ixx="0.00013051726595754"
        ixy="4.11179123299775E-07"
        ixz="-2.02778699571397E-08"
        iyy="0.000330666767704576"
        iyz="1.51165378052728E-06"
        izz="0.000241825516008571" />
    </inertial>
    <visual>
      <origin
        xyz="0 0 0"
        rpy="0 0 0" />
      <geometry>
        <mesh
          filename="package://blue02/meshes/base_link.STL" />
      </geometry>
      <material
        name="">
        <color
          rgba="0.752941176470588 0.752941176470588 0.752941176470588 1" />
      </material>
    </visual>
    <collision>
      <origin
        xyz="0 0 0"
        rpy="0 0 0" />
      <geometry>
        <mesh
          filename="package://blue02/meshes/base_link.STL" />
      </geometry>
    </collision>
  </link>
  <link
    name="Link1">
    <inertial>
      <origin
        xyz="-0.0343174966874236 -0.00344507312875845 -0.0230620305997283"
        rpy="0 0 0" />
      <mass
        value="0.0168488269980785" />
      <inertia
        ixx="2.77327908754805E-06"
        ixy="-3.22105701183017E-07"
        ixz="-2.26775561062583E-12"
        iyy="1.21496555654029E-05"
        iyz="-5.00426200709654E-13"
        izz="9.92161165241104E-06" />
    </inertial>
    <visual>
      <origin
        xyz="0 0 0"
        rpy="0 0 0" />
      <geometry>
        <mesh
          filename="package://blue02/meshes/Link1.STL" />
      </geometry>
      <material
        name="">
        <color
          rgba="1 1 1 1" />
      </material>
    </visual>
    <collision>
      <origin
        xyz="0 0 0"
        rpy="0 0 0" />
      <geometry>
        <mesh
          filename="package://blue02/meshes/Link1.STL" />
      </geometry>
    </collision>
  </link>
  <joint
    name="Joint1"
    type="continuous">
    <origin
      xyz="0.004938 -0.0395 0.040325"
      rpy="-1.5708 0.31922 1.5708" />
    <parent
      link="base_link" />
    <child
      link="Link1" />
    <axis
      xyz="0 0 -1" />
    <limit
      lower="0"
      upper="0"
      effort="0"
      velocity="0" />
  </joint>
  <link
    name="Link2">
    <inertial>
      <origin
        xyz="0.0126 0.0119177461611013 1.196959198424E-14"
        rpy="0 0 0" />
      <mass
        value="0.00283590714079142" />
      <inertia
        ixx="1.38027104044294E-07"
        ixy="-3.51738268802297E-24"
        ixz="1.79362883603125E-23"
        iyy="1.58449114328455E-07"
        iyz="3.97046694025453E-23"
        izz="2.69919583243166E-07" />
    </inertial>
    <visual>
      <origin
        xyz="0 0 0"
        rpy="0 0 0" />
      <geometry>
        <mesh
          filename="package://blue02/meshes/Link2.STL" />
      </geometry>
      <material
        name="">
        <color
          rgba="0.250980392156863 0.250980392156863 0.250980392156863 1" />
      </material>
    </visual>
    <collision>
      <origin
        xyz="0 0 0"
        rpy="0 0 0" />
      <geometry>
        <mesh
          filename="package://blue02/meshes/Link2.STL" />
      </geometry>
    </collision>
  </link>
  <joint
    name="Joint2"
    type="continuous">
    <origin
      xyz="-0.08 -0.004 -0.010662"
      rpy="1.6021 1.5708 0" />
    <parent
      link="Link1" />
    <child
      link="Link2" />
    <axis
      xyz="1 0 0" />
    <limit
      lower="0"
      upper="0"
      effort="0"
      velocity="0" />
  </joint>
  <link
    name="Link3">
    <inertial>
      <origin
        xyz="-0.0301999999999765 0.0420000000000081 8.40492935319515E-09"
        rpy="0 0 0" />
      <mass
        value="0.0115483860896402" />
      <inertia
        ixx="6.99727115654008E-06"
        ixy="6.05605579279737E-06"
        ixz="3.28225267061041E-21"
        iyy="5.72454936139626E-06"
        iyz="-4.02340649945793E-21"
        izz="1.2540943263813E-05" />
    </inertial>
    <visual>
      <origin
        xyz="0 0 0"
        rpy="0 0 0" />
      <geometry>
        <mesh
          filename="package://blue02/meshes/Link3.STL" />
      </geometry>
      <material
        name="">
        <color
          rgba="1 1 1 1" />
      </material>
    </visual>
    <collision>
      <origin
        xyz="0 0 0"
        rpy="0 0 0" />
      <geometry>
        <mesh
          filename="package://blue02/meshes/Link3.STL" />
      </geometry>
    </collision>
  </link>
  <joint
    name="Joint3"
    type="continuous">
    <origin
      xyz="0.0214 0.02 0"
      rpy="1.6389 -1.5708 -2.0564" />
    <parent
      link="Link2" />
    <child
      link="Link3" />
    <axis
      xyz="-1 0 0" />
    <limit
      lower="0"
      upper="0"
      effort="0"
      velocity="0" />
  </joint>
  <link
    name="Link4">
    <inertial>
      <origin
        xyz="-0.0301999999999559 0.042000000000024 8.40489629977403E-09"
        rpy="0 0 0" />
      <mass
        value="0.0115483860896403" />
      <inertia
        ixx="6.9972711565401E-06"
        ixy="6.05605579279738E-06"
        ixz="-3.49401090742399E-21"
        iyy="5.72454936139628E-06"
        iyz="2.32934060494933E-21"
        izz="1.25409432638131E-05" />
    </inertial>
    <visual>
      <origin
        xyz="0 0 0"
        rpy="0 0 0" />
      <geometry>
        <mesh
          filename="package://blue02/meshes/Link4.STL" />
      </geometry>
      <material
        name="">
        <color
          rgba="1 1 1 1" />
      </material>
    </visual>
    <collision>
      <origin
        xyz="0 0 0"
        rpy="0 0 0" />
      <geometry>
        <mesh
          filename="package://blue02/meshes/Link4.STL" />
      </geometry>
    </collision>
  </link>
  <joint
    name="Joint4"
    type="continuous">
    <origin
      xyz="0.0038 0.02 0"
      rpy="1.55 -1.5708 -2.012" />
    <parent
      link="Link2" />
    <child
      link="Link4" />
    <axis
      xyz="-1 0 0" />
    <limit
      lower="0"
      upper="0"
      effort="0"
      velocity="0" />
  </joint>
  <link
    name="Link5">
    <inertial>
      <origin
        xyz="5.31380495161216E-14 0.00991774616108076 -6.93889390390723E-17"
        rpy="0 0 0" />
      <mass
        value="0.00283590714079142" />
      <inertia
        ixx="1.38027104044293E-07"
        ixy="-3.00383054696694E-21"
        ixz="9.21812187730928E-23"
        iyy="1.58449114328455E-07"
        iyz="4.55908866414727E-20"
        izz="2.69919583243166E-07" />
    </inertial>
    <visual>
      <origin
        xyz="0 0 0"
        rpy="0 0 0" />
      <geometry>
        <mesh
          filename="package://blue02/meshes/Link5.STL" />
      </geometry>
      <material
        name="">
        <color
          rgba="0.250980392156863 0.250980392156863 0.250980392156863 1" />
      </material>
    </visual>
    <collision>
      <origin
        xyz="0 0 0"
        rpy="0 0 0" />
      <geometry>
        <mesh
          filename="package://blue02/meshes/Link5.STL" />
      </geometry>
    </collision>
  </link>
  <joint
    name="Joint5"
    type="fixed">
    <origin
      xyz="-0.0604 0.10399 -0.0013692"
      rpy="-1.5708 -1.1845 -1.5708" />
    <parent
      link="Link4" />
    <child
      link="Link5" />
    <axis
      xyz="0 0 0" />
    <limit
      lower="0"
      upper="0"
      effort="0"
      velocity="0" />
  </joint>
</robot>